/**
 * @athenna/common
 *
 * (c) Jo√£o Lenon <lenon@athenna.io>
 *
 * For the full copyright and license information, please view the LICENSE
 * file that was distributed with this source code.
 */

import { Exception } from '#src'
import { Test, type Context } from '@athenna/test'

export default class ExceptionTest {
  @Test()
  public async shouldBeAbleToCreateANewException({ assert }: Context) {
    const exception = new Exception({ message: 'My custom instance error' })

    const errorJson = exception.toJSON()

    assert.equal(errorJson.status, 500)
    assert.equal(errorJson.code, 'EXCEPTION')
    assert.equal(errorJson.name, 'Exception')
    assert.equal(errorJson.message, 'My custom instance error')
  }

  @Test()
  public async shouldBeAbleToCreateANewExceptionFromVanillaErrors({ assert }: Context) {
    const exception = new Error('My custom instance error').toAthennaException({
      status: 0,
      code: 'EXCEPTION',
      name: 'Exception'
    })

    const errorJson = exception.toJSON()

    assert.equal(errorJson.status, 0)
    assert.equal(errorJson.code, 'EXCEPTION')
    assert.equal(errorJson.name, 'Exception')
    assert.equal(errorJson.message, 'My custom instance error')
  }

  @Test()
  public async shouldBeAbleToExtendExceptionClassToCreateANewException({ assert }: Context) {
    class InternalServerException extends Exception {
      constructor(content = 'Internal Server Error', status = 500) {
        super({ message: content, status, code: 'E_RUNTIME_EXCEPTION', help: 'Restart computer.' })
      }
    }

    const exception = new InternalServerException()

    const errorJson = exception.toJSON(false)

    assert.isUndefined(errorJson.stack)
    assert.equal(errorJson.status, 500)
    assert.equal(errorJson.code, 'E_RUNTIME_EXCEPTION')
    assert.equal(errorJson.name, 'InternalServerException')
    assert.equal(errorJson.message, 'Internal Server Error')
  }

  @Test()
  public async shouldBeAbleToPrettifyTheException({ assert }: Context) {
    class InternalServerException extends Exception {
      constructor(content = 'Internal Server Error.', status = 500) {
        super({
          status,
          message: content,
          code: 'E_RUNTIME_EXCEPTION',
          help: 'Restart your computer, works always. üëç'
        })
      }
    }

    const exception = new InternalServerException()

    const prettyError = await exception.prettify()

    console.log(prettyError)

    assert.isDefined(prettyError)
    assert.typeOf(prettyError, 'string')
  }

  @Test()
  public async shouldBeAbleToPrettifyTheExceptionWithDetails({ assert }: Context) {
    class InternalServerException extends Exception {
      constructor(content = 'Internal Server Error.', status = 500) {
        super({
          status,
          message: content,
          details: ['Machine error', 'Runtime error'],
          code: 'E_RUNTIME_EXCEPTION',
          help: 'Restart your computer, works always. üëç'
        })
      }
    }

    const exception = new InternalServerException()
    const prettyError = await exception.prettify()

    console.log(prettyError)

    assert.isDefined(prettyError)
    assert.typeOf(prettyError, 'string')
  }
}
